[2023-11-21T08:02:31.029+0545] {taskinstance.py:1159} INFO - Dependencies all met for dep_context=non-requeueable deps ti=<TaskInstance: podcast_summery.get_episode scheduled__2023-11-20T00:00:00+00:00 [queued]>
[2023-11-21T08:02:31.033+0545] {taskinstance.py:1159} INFO - Dependencies all met for dep_context=requeueable deps ti=<TaskInstance: podcast_summery.get_episode scheduled__2023-11-20T00:00:00+00:00 [queued]>
[2023-11-21T08:02:31.034+0545] {taskinstance.py:1361} INFO - Starting attempt 1 of 1
[2023-11-21T08:02:31.042+0545] {taskinstance.py:1382} INFO - Executing <Task(_PythonDecoratedOperator): get_episode> on 2023-11-20 00:00:00+00:00
[2023-11-21T08:02:31.046+0545] {standard_task_runner.py:57} INFO - Started process 166073 to run task
[2023-11-21T08:02:31.048+0545] {standard_task_runner.py:84} INFO - Running: ['airflow', 'tasks', 'run', 'podcast_summery', 'get_episode', 'scheduled__2023-11-20T00:00:00+00:00', '--job-id', '56', '--raw', '--subdir', 'DAGS_FOLDER/podcast_summery.py', '--cfg-path', '/tmp/tmpimhvlfno']
[2023-11-21T08:02:31.048+0545] {standard_task_runner.py:85} INFO - Job 56: Subtask get_episode
[2023-11-21T08:02:31.071+0545] {task_command.py:416} INFO - Running <TaskInstance: podcast_summery.get_episode scheduled__2023-11-20T00:00:00+00:00 [running]> on host dwarka.dwarka
[2023-11-21T08:02:31.108+0545] {taskinstance.py:1662} INFO - Exporting env vars: AIRFLOW_CTX_DAG_OWNER='airflow' AIRFLOW_CTX_DAG_ID='podcast_summery' AIRFLOW_CTX_TASK_ID='get_episode' AIRFLOW_CTX_EXECUTION_DATE='2023-11-20T00:00:00+00:00' AIRFLOW_CTX_TRY_NUMBER='1' AIRFLOW_CTX_DAG_RUN_ID='scheduled__2023-11-20T00:00:00+00:00'
[2023-11-21T08:02:31.113+0545] {taskinstance.py:1937} ERROR - Task failed with exception
Traceback (most recent call last):
  File "/home/ace/aiflow_project/lib/python3.11/site-packages/urllib3/connection.py", line 203, in _new_conn
    sock = connection.create_connection(
           ^^^^^^^^^^^^^^^^^^^^^^^^^^^^^
  File "/home/ace/aiflow_project/lib/python3.11/site-packages/urllib3/util/connection.py", line 60, in create_connection
    for res in socket.getaddrinfo(host, port, family, socket.SOCK_STREAM):
               ^^^^^^^^^^^^^^^^^^^^^^^^^^^^^^^^^^^^^^^^^^^^^^^^^^^^^^^^^^
  File "/usr/lib/python3.11/socket.py", line 962, in getaddrinfo
    for res in _socket.getaddrinfo(host, port, family, type, proto, flags):
               ^^^^^^^^^^^^^^^^^^^^^^^^^^^^^^^^^^^^^^^^^^^^^^^^^^^^^^^^^^^
socket.gaierror: [Errno -2] Name or service not known

The above exception was the direct cause of the following exception:

Traceback (most recent call last):
  File "/home/ace/aiflow_project/lib/python3.11/site-packages/urllib3/connectionpool.py", line 790, in urlopen
    response = self._make_request(
               ^^^^^^^^^^^^^^^^^^^
  File "/home/ace/aiflow_project/lib/python3.11/site-packages/urllib3/connectionpool.py", line 491, in _make_request
    raise new_e
  File "/home/ace/aiflow_project/lib/python3.11/site-packages/urllib3/connectionpool.py", line 467, in _make_request
    self._validate_conn(conn)
  File "/home/ace/aiflow_project/lib/python3.11/site-packages/urllib3/connectionpool.py", line 1096, in _validate_conn
    conn.connect()
  File "/home/ace/aiflow_project/lib/python3.11/site-packages/urllib3/connection.py", line 611, in connect
    self.sock = sock = self._new_conn()
                       ^^^^^^^^^^^^^^^^
  File "/home/ace/aiflow_project/lib/python3.11/site-packages/urllib3/connection.py", line 210, in _new_conn
    raise NameResolutionError(self.host, self, e) from e
urllib3.exceptions.NameResolutionError: <urllib3.connection.HTTPSConnection object at 0x7f2a486b8b50>: Failed to resolve 'marketplace.org' ([Errno -2] Name or service not known)

The above exception was the direct cause of the following exception:

Traceback (most recent call last):
  File "/home/ace/aiflow_project/lib/python3.11/site-packages/requests/adapters.py", line 486, in send
    resp = conn.urlopen(
           ^^^^^^^^^^^^^
  File "/home/ace/aiflow_project/lib/python3.11/site-packages/urllib3/connectionpool.py", line 844, in urlopen
    retries = retries.increment(
              ^^^^^^^^^^^^^^^^^^
  File "/home/ace/aiflow_project/lib/python3.11/site-packages/urllib3/util/retry.py", line 515, in increment
    raise MaxRetryError(_pool, url, reason) from reason  # type: ignore[arg-type]
    ^^^^^^^^^^^^^^^^^^^^^^^^^^^^^^^^^^^^^^^^^^^^^^^^^^^
urllib3.exceptions.MaxRetryError: HTTPSConnectionPool(host='marketplace.org', port=443): Max retries exceeded with url: /feed/podcast/marketplace (Caused by NameResolutionError("<urllib3.connection.HTTPSConnection object at 0x7f2a486b8b50>: Failed to resolve 'marketplace.org' ([Errno -2] Name or service not known)"))

During handling of the above exception, another exception occurred:

Traceback (most recent call last):
  File "/home/ace/aiflow_project/lib/python3.11/site-packages/airflow/decorators/base.py", line 221, in execute
    return_value = super().execute(context)
                   ^^^^^^^^^^^^^^^^^^^^^^^^
  File "/home/ace/aiflow_project/lib/python3.11/site-packages/airflow/operators/python.py", line 192, in execute
    return_value = self.execute_callable()
                   ^^^^^^^^^^^^^^^^^^^^^^^
  File "/home/ace/aiflow_project/lib/python3.11/site-packages/airflow/operators/python.py", line 209, in execute_callable
    return self.python_callable(*self.op_args, **self.op_kwargs)
           ^^^^^^^^^^^^^^^^^^^^^^^^^^^^^^^^^^^^^^^^^^^^^^^^^^^^^
  File "/home/ace/airflow/dags/podcast_summery.py", line 34, in get_episode
    data=requests.get("https://marketplace.org/feed/podcast/marketplace")
         ^^^^^^^^^^^^^^^^^^^^^^^^^^^^^^^^^^^^^^^^^^^^^^^^^^^^^^^^^^^^^^^^
  File "/home/ace/aiflow_project/lib/python3.11/site-packages/requests/api.py", line 73, in get
    return request("get", url, params=params, **kwargs)
           ^^^^^^^^^^^^^^^^^^^^^^^^^^^^^^^^^^^^^^^^^^^^
  File "/home/ace/aiflow_project/lib/python3.11/site-packages/requests/api.py", line 59, in request
    return session.request(method=method, url=url, **kwargs)
           ^^^^^^^^^^^^^^^^^^^^^^^^^^^^^^^^^^^^^^^^^^^^^^^^^
  File "/home/ace/aiflow_project/lib/python3.11/site-packages/requests/sessions.py", line 589, in request
    resp = self.send(prep, **send_kwargs)
           ^^^^^^^^^^^^^^^^^^^^^^^^^^^^^^
  File "/home/ace/aiflow_project/lib/python3.11/site-packages/requests/sessions.py", line 703, in send
    r = adapter.send(request, **kwargs)
        ^^^^^^^^^^^^^^^^^^^^^^^^^^^^^^^
  File "/home/ace/aiflow_project/lib/python3.11/site-packages/requests/adapters.py", line 519, in send
    raise ConnectionError(e, request=request)
requests.exceptions.ConnectionError: HTTPSConnectionPool(host='marketplace.org', port=443): Max retries exceeded with url: /feed/podcast/marketplace (Caused by NameResolutionError("<urllib3.connection.HTTPSConnection object at 0x7f2a486b8b50>: Failed to resolve 'marketplace.org' ([Errno -2] Name or service not known)"))
[2023-11-21T08:02:31.121+0545] {taskinstance.py:1400} INFO - Marking task as FAILED. dag_id=podcast_summery, task_id=get_episode, execution_date=20231120T000000, start_date=20231121T021731, end_date=20231121T021731
[2023-11-21T08:02:31.128+0545] {standard_task_runner.py:104} ERROR - Failed to execute job 56 for task get_episode (HTTPSConnectionPool(host='marketplace.org', port=443): Max retries exceeded with url: /feed/podcast/marketplace (Caused by NameResolutionError("<urllib3.connection.HTTPSConnection object at 0x7f2a486b8b50>: Failed to resolve 'marketplace.org' ([Errno -2] Name or service not known)")); 166073)
[2023-11-21T08:02:31.139+0545] {local_task_job_runner.py:228} INFO - Task exited with return code 1
[2023-11-21T08:02:31.150+0545] {taskinstance.py:2778} INFO - 0 downstream tasks scheduled from follow-on schedule check
